Workbook
Name Slicer_Category: #N/A
Name Slicer_month: #N/A
Name Slicer_State: #N/A

Sheet project_excel
J1: product name | K1: Sales | M1: cust_name | N1: Count of CustomerID | P1: cust_name | Q1: Sales
J2: Product_1 | K2: 35535 | M2: Customer_10 | N2: 6 | P2: Customer_1132 | Q2: 312536
J3: Product_10 | K3: 4475 | M3: Customer_100 | N3: 6 | P3: Customer_114 | Q3: 310151 | S3: Total_sales | U3: total sales target | W3: retention rate
A4: category | B4: Sales | J4: Product_100 | K4: 14931 | M4: Customer_1001 | N4: 9 | P4: Customer_1299 | Q4: 290939 | S4: =SUM(orders[Sales]) -> 31043255 | U4: =SUM(sales_targets[Target Sales]) -> 326307341 | W4: =U9/S17 -> 1
A5: Accessories | B5: 7900741 | J5: Product_1000 | K5: 17015 | M5: Customer_1008 | N5: 7 | P5: Customer_1398 | Q5: 325413
A6: Electronics | B6: 8752739 | J6: Product_1001 | K6: 42848 | M6: Customer_1017 | N6: 7 | P6: Customer_1430 | Q6: 325695
A7: Furniture | B7: 6294221 | J7: Product_1002 | K7: 73679 | M7: Customer_1030 | N7: 9 | P7: Customer_162 | Q7: 387548
A8: Stationery | B8: 7340305 | J8: Product_1003 | K8: 64960 | M8: Customer_1048 | N8: 6 | P8: Customer_223 | Q8: 326477 | S8: total_profit | U8: total repeated people | W8: total_growth%
A9: Grand Total | B9: 30288006 | J9: Product_1004 | K9: 114927 | M9: Customer_1051 | N9: 11 | P9: Customer_39 | Q9: 320925 | S9: =SUM(orders[Profit]) -> 5316186.8 | U9: =SUM(orders[repeated_people]) -> 1200 | W9: =SUM(Table6_1[mom growth%]) -> -0.11990433
J10: Product_1005 | K10: 5474 | M10: Customer_1060 | N10: 6 | P10: Customer_641 | Q10: 327191
J11: Product_1006 | K11: 5134 | M11: Customer_1061 | N11: 7 | P11: Customer_981 | Q11: 291055
J12: Product_1007 | K12: 23909 | M12: Customer_1063 | N12: 5 | P12: Grand Total | Q12: 3217930 | S12: No.of.orders | U12: Target Achievement %
J13: Product_1008 | K13: 48873 | M13: Customer_1068 | N13: 9 | S13: =COUNTA(orders[OrderID]) -> 1200 | U13: =(S4/U4) -> 0.095135019
J14: Product_1010 | K14: 19041 | M14: Customer_108 | N14: 6
B15: state | C15: Sales | J15: Product_1011 | K15: 8270 | M15: Customer_1084 | N15: 2
B16: Delhi | C16: 30288006 | J16: Product_1012 | K16: 48357 | M16: Customer_1114 | N16: 5 | S16: No.of.customers | U16: inventory turnover
B17: Karnataka | C17: 36375020 | J17: Product_1014 | K17: 76821 | M17: Customer_1116 | N17: 7 | S17: =COUNTA(_xlfn.UNIQUE(customers[CustomerID])) -> 1200 | U17: =U21/U25 -> 286883.99
B18: Kerala | C18: 40226052 | J18: Product_1015 | K18: 9631 | M18: Customer_1119 | N18: 6
B19: Maharashtra | C19: 38003322 | J19: Product_1016 | K19: 25759 | M19: Customer_1126 | N19: 11
B20: Tamil Nadu | C20: 38569250 | J20: Product_1017 | K20: 54787 | M20: Customer_1129 | N20: 7 | S20: average ordervalue | U20: total cogs
B21: Telangana | C21: 35826109 | J21: Product_1019 | K21: 62303 | M21: Customer_113 | N21: 8 | S21: =S4/S13 -> 25869.379 | U21: =SUM(orders[cost of goods]) -> 142015464
B22: West Bengal | C22: 35783371 | J22: Product_102 | K22: 54126 | M22: Customer_1132 | N22: 9
B23: Grand Total | C23: 255071130 | J23: Product_1023 | K23: 47828 | M23: Customer_114 | N23: 11
J24: Product_1025 | K24: 47021 | M24: Customer_1159 | N24: 5 | S24: profit margin | U24: avg inventory stock
J25: Product_1026 | K25: 27939 | M25: Customer_1176 | N25: 10 | S25: =S9/S4 -> 0.17125095 | U25: =AVERAGE(inventory[Current Stock]) -> 495.0275
J26: Product_1027 | K26: 19730 | M26: Customer_1179 | N26: 4
J27: Product_1028 | K27: 21491 | M27: Customer_1189 | N27: 5
J28: Product_103 | K28: 19394 | M28: Customer_1192 | N28: 4
J29: Product_1030 | K29: 10809 | M29: Customer_1207 | N29: 7
J30: Product_1031 | K30: 47167 | M30: Customer_1218 | N30: 4
J31: Product_1033 | K31: 78702 | M31: Customer_1219 | N31: 4 | S31: cust_name | T31: Count of CustomerID
J32: Product_1034 | K32: 21057 | M32: Customer_1221 | N32: 2 | S32: Customer_981 | T32: 12
J33: Product_1035 | K33: 72926 | M33: Customer_1222 | N33: 9 | S33: Customer_641 | T33: 12
J34: Product_1039 | K34: 12190 | M34: Customer_1226 | N34: 4 | S34: Customer_527 | T34: 13
J35: Product_1041 | K35: 32431 | M35: Customer_1229 | N35: 9 | S35: Customer_223 | T35: 12
J36: Product_1042 | K36: 64304 | M36: Customer_1237 | N36: 8 | S36: Customer_196 | T36: 14
J37: Product_1044 | K37: 33873 | M37: Customer_1253 | N37: 4 | S37: Customer_162 | T37: 13
J38: Product_1046 | K38: 37386 | M38: Customer_1254 | N38: 4 | S38: Customer_1299 | T38: 12
J39: Product_1047 | K39: 23565 | M39: Customer_1258 | N39: 4 | S39: Customer_114 | T39: 11
J40: Product_1048 | K40: 40954 | M40: Customer_127 | N40: 9 | S40: Customer_1126 | T40: 11
...

Sheet Sheet1
D5: Retention_rate
B6: inventory turnover | D6: =project_excel!W4 -> 1
B7: =project_excel!U17 -> 286883.99
D8: Total Repeated_people
D9: =project_excel!U9 -> 1200
B10: Total_profit
B11: =project_excel!S9 -> 5316186.8 | D11: Total_growth%
D12: =project_excel!W9 -> -0.11990433
B14: Total_sales
B15: =project_excel!S4 -> 31043255
B18: profit margin
B19: =project_excel!$S$25 -> 0.17125095
B21: Target achievement
B22: =project_excel!U13 -> 0.095135019

Sheet Sheet2
H2: EXECUTIVE DASHBOARD
K5: Row Labels | L5: Sum of Current Stock
K6: P0006 | L6: 0
K7: P0084 | L7: 2
K8: P0106 | L8: 0
K9: P0167 | L9: 3
K10: P0305 | L10: 4
K11: P0312 | L11: 4
K12: P0463 | L12: 1
K13: P0854 | L13: 1
K14: Grand Total | L14: 15

Sheet customers
A1: CustomerID | B1: Name | C1: City | D1: State | E1: Segment
A2: C0001 | B2: Customer_1 | C2: Bangalore | D2: Maharashtra | E2: Home Office
A3: C0002 | B3: Customer_2 | C3: Kolkata | D3: Telangana | E3: Home Office
A4: C0003 | B4: Customer_3 | C4: Delhi | D4: Telangana | E4: Home Office
A5: C0004 | B5: Customer_4 | C5: Mumbai | D5: Tamil Nadu | E5: Home Office
A6: C0005 | B6: Customer_5 | C6: Mumbai | D6: Delhi | E6: Home Office
A7: C0006 | B7: Customer_6 | C7: Kolkata | D7: Telangana | E7: Corporate
A8: C0007 | B8: Customer_7 | C8: Bangalore | D8: Kerala | E8: Corporate
A9: C0008 | B9: Customer_8 | C9: Delhi | D9: Maharashtra | E9: Corporate
A10: C0009 | B10: Customer_9 | C10: Hyderabad | D10: Kerala | E10: Corporate
A11: C0010 | B11: Customer_10 | C11: Bangalore | D11: Delhi | E11: Home Office
A12: C0011 | B12: Customer_11 | C12: Pune | D12: Tamil Nadu | E12: Corporate
... A1201: C1200 | B1201: Customer_1200 | C1201: Pune | D1201: Karnataka | E1201: Consumer

Sheet inventory
A1: ProductID | B1: Current Stock | C1: Reorder Level | D1: stock status
A2: P0001 | B2: 37 | C2: 93 | D2: =IF(inventory[[#This Row],[Current Stock]]<=inventory[[#This Row],[Reorder Level]],"Reorder","Available") -> Reorder
A3: P0002 | B3: 691 | C3: 190 | D3: =IF(inventory[[#This Row],[Current Stock]]<=inventory[[#This Row],[Reorder Level]],"Reorder","Available") -> Available
A4: P0003 | B4: 812 | C4: 44 | D4: =IF(inventory[[#This Row],[Current Stock]]<=inventory[[#This Row],[Reorder Level]],"Reorder","Available") -> Available
A5: P0004 | B5: 559 | C5: 137 | D5: =IF(inventory[[#This Row],[Current Stock]]<=inventory[[#This Row],[Reorder Level]],"Reorder","Available") -> Available
A6: P0005 | B6: 639 | C6: 44 | D6: =IF(inventory[[#This Row],[Current Stock]]<=inventory[[#This Row],[Reorder Level]],"Reorder","Available") -> Available
A7: P0006 | B7: 0 | C7: 113 | D7: =IF(inventory[[#This Row],[Current Stock]]<=inventory[[#This Row],[Reorder Level]],"Reorder","Available") -> Reorder
A8: P0007 | B8: 30 | C8: 103 | D8: =IF(inventory[[#This Row],[Current Stock]]<=inventory[[#This Row],[Reorder Level]],"Reorder","Available") -> Reorder
A9: P0008 | B9: 35 | C9: 95 | D9: =IF(inventory[[#This Row],[Current Stock]]<=inventory[[#This Row],[Reorder Level]],"Reorder","Available") -> Reorder
A10: P0009 | B10: 158 | C10: 134 | D10: =IF(inventory[[#This Row],[Current Stock]]<=inventory[[#This Row],[Reorder Level]],"Reorder","Available") -> Available
A11: P0010 | B11: 990 | C11: 167 | D11: =IF(inventory[[#This Row],[Current Stock]]<=inventory[[#This Row],[Reorder Level]],"Reorder","Available") -> Available
A12: P0011 | B12: 634 | C12: 70 | D12: =IF(inventory[[#This Row],[Current Stock]]<=inventory[[#This Row],[Reorder Level]],"Reorder","Available") -> Available
A13: P0012 | B13: 782 | C13: 171 | D13: =IF(inventory[[#This Row],[Current Stock]]<=inventory[[#This Row],[Reorder Level]],"Reorder","Available") -> Available
... A1201: P1200 | B1201: 717 | C1201: 98 | D1201: =IF(inventory[[#This Row],[Current Stock]]<=inventory[[#This Row],[Reorder Level]],"Reorder","Available") -> Available

Sheet orders
A1: OrderID | B1: Date | C1: CustomerID | D1: ProductID | E1: Quantity | F1: Sales | G1: Profit | H1: PM% | I1: cost of goods | J1: month | K1: Cost Price | L1: count_id | M1: repeated_people | N1: mom_growth | Q1: month | R1: sales
A2: O002662 | B2: 45963 | C2: C0001 | D2: P0329 | E2: 8 | F2: 24995 | G2: 5824.73 | H2: =(orders[[#This Row],[Profit]]/orders[[#This Row],[Sales]])*100 -> 23.303581 | I2: =orders[[#This Row],[Quantity]]*orders[[#This Row],[Cost Price]] -> 249488 | J2: =TEXT(orders[[#This Row],[Date]],"mmm") -> Nov | K2: 31186 | L2: 7 | M2: =COUNT(orders[[#This Row],[count_id]]) -> 1 | Q2: =TEXT(orders[[#This Row],[Date]],"mmm") -> Nov | R2: 24995
A3: O003761 | B3: 45917 | C3: C0001 | D3: P0586 | E3: 9 | F3: 2084 | G3: 152.69 | H3: =(orders[[#This Row],[Profit]]/orders[[#This Row],[Sales]])*100 -> 7.3267754 | I3: =orders[[#This Row],[Quantity]]*orders[[#This Row],[Cost Price]] -> 171657 | J3: =TEXT(orders[[#This Row],[Date]],"mmm") -> Sep | K3: 19073 | L3: 6 | M3: =COUNT(orders[[#This Row],[count_id]]) -> 1 | Q3: =TEXT(orders[[#This Row],[Date]],"mmm") -> Sep | R3: 2084
A4: O005458 | B4: 45663 | C4: C0001 | D4: P0438 | E4: 9 | F4: 7893 | G4: 620.88 | H4: =(orders[[#This Row],[Profit]]/orders[[#This Row],[Sales]])*100 -> 7.8662106 | I4: =orders[[#This Row],[Quantity]]*orders[[#This Row],[Cost Price]] -> 125406 | J4: =TEXT(orders[[#This Row],[Date]],"mmm") -> Jan | K4: 13934 | L4: 6 | M4: =COUNT(orders[[#This Row],[count_id]]) -> 1 | Q4: =TEXT(orders[[#This Row],[Date]],"mmm") -> Jan | R4: 7893
A5: O005927 | B5: 45307 | C5: C0001 | D5: P1055 | E5: 8 | F5: 33075 | G5: 2801.54 | H5: =(orders[[#This Row],[Profit]]/orders[[#This Row],[Sales]])*100 -> 8.4702646 | I5: =orders[[#This Row],[Quantity]]*orders[[#This Row],[Cost Price]] -> 172976 | J5: =TEXT(orders[[#This Row],[Date]],"mmm") -> Jan | K5: 21622 | L5: 9 | M5: =COUNT(orders[[#This Row],[count_id]]) -> 1 | Q5: =TEXT(orders[[#This Row],[Date]],"mmm") -> Jan | R5: 33075
A6: O006774 | B6: 45963 | C6: C0001 | D6: P0872 | E6: 3 | F6: 832 | G6: 240.6 | H6: =(orders[[#This Row],[Profit]]/orders[[#This Row],[Sales]])*100 -> 28.918269 | I6: =orders[[#This Row],[Quantity]]*orders[[#This Row],[Cost Price]] -> 46983 | J6: =TEXT(orders[[#This Row],[Date]],"mmm") -> Nov | K6: 15661 | L6: 9 | M6: =COUNT(orders[[#This Row],[count_id]]) -> 1 | Q6: =TEXT(orders[[#This Row],[Date]],"mmm") -> Nov | R6: 832
A7: O006847 | B7: 45885 | C7: C0001 | D7: P1093 | E7: 5 | F7: 8438 | G7: 1025.85 | H7: =(orders[[#This Row],[Profit]]/orders[[#This Row],[Sales]])*100 -> 12.157502 | I7: =orders[[#This Row],[Quantity]]*orders[[#This Row],[Cost Price]] -> 203850 | J7: =TEXT(orders[[#This Row],[Date]],"mmm") -> Aug | K7: 40770 | L7: 4 | M7: =COUNT(orders[[#This Row],[count_id]]) -> 1 | Q7: =TEXT(orders[[#This Row],[Date]],"mmm") -> Aug | R7: 8438
A8: O007076 | B8: 45659 | C8: C0001 | D8: P0483 | E8: 6 | F8: 12188 | G8: 3653.15 | H8: =(orders[[#This Row],[Profit]]/orders[[#This Row],[Sales]])*100 -> 29.973334 | I8: =orders[[#This Row],[Quantity]]*orders[[#This Row],[Cost Price]] -> 123852 | J8: =TEXT(orders[[#This Row],[Date]],"mmm") -> Jan | K8: 20642 | L8: 9 | M8: =COUNT(orders[[#This Row],[count_id]]) -> 1 | Q8: =TEXT(orders[[#This Row],[Date]],"mmm") -> Jan | R8: 12188
A9: O000221 | B9: 45476 | C9: C0002 | D9: P0805 | E9: 4 | F9: 21965 | G9: 2323.08 | H9: =(orders[[#This Row],[Profit]]/orders[[#This Row],[Sales]])*100 -> 10.57628 | I9: =orders[[#This Row],[Quantity]]*orders[[#This Row],[Cost Price]] -> 64436 | J9: =TEXT(orders[[#This Row],[Date]],"mmm") -> Jul | K9: 16109 | L9: 6 | M9: =COUNT(orders[[#This Row],[count_id]]) -> 1 | Q9: =TEXT(orders[[#This Row],[Date]],"mmm") -> Jul | R9: 21965
A10: O000993 | B10: 45900 | C10: C0002 | D10: P0176 | E10: 1 | F10: 5930 | G10: 1584.95 | H10: =(orders[[#This Row],[Profit]]/orders[[#This Row],[Sales]])*100 -> 26.727656 | I10: =orders[[#This Row],[Quantity]]*orders[[#This Row],[Cost Price]] -> 26854 | J10: =TEXT(orders[[#This Row],[Date]],"mmm") -> Aug | K10: 26854 | L10: 4 | M10: =COUNT(orders[[#This Row],[count_id]]) -> 1 | Q10: =TEXT(orders[[#This Row],[Date]],"mmm") -> Aug | R10: 5930
A11: O001981 | B11: 45612 | C11: C0002 | D11: P0203 | E11: 9 | F11: 6169 | G11: 594.2 | H11: =(orders[[#This Row],[Profit]]/orders[[#This Row],[Sales]])*100 -> 9.6320311 | I11: =orders[[#This Row],[Quantity]]*orders[[#This Row],[Cost Price]] -> 341334 | J11: =TEXT(orders[[#This Row],[Date]],"mmm") -> Nov | K11: 37926 | L11: 6 | M11: =COUNT(orders[[#This Row],[count_id]]) -> 1 | Q11: =TEXT(orders[[#This Row],[Date]],"mmm") -> Nov | R11: 6169
A12: O002932 | B12: 45458 | C12: C0002 | D12: P0679 | E12: 8 | F12: 43552 | G12: 5461.55 | H12: =(orders[[#This Row],[Profit]]/orders[[#This Row],[Sales]])*100 -> 12.540297 | I12: =orders[[#This Row],[Quantity]]*orders[[#This Row],[Cost Price]] -> 110040 | J12: =TEXT(orders[[#This Row],[Date]],"mmm") -> Jun | K12: 13755 | L12: 9 | M12: =COUNT(orders[[#This Row],[count_id]]) -> 1 | Q12: =TEXT(orders[[#This Row],[Date]],"mmm") -> Jun | R12: 43552
A13: O004678 | B13: 45701 | C13: C0002 | D13: P1122 | E13: 6 | F13: 25461 | G13: 4819.75 | H13: =(orders[[#This Row],[Profit]]/orders[[#This Row],[Sales]])*100 -> 18.929932 | I13: =orders[[#This Row],[Quantity]]*orders[[#This Row],[Cost Price]] -> 281898 | J13: =TEXT(orders[[#This Row],[Date]],"mmm") -> Feb | K13: 46983 | L13: 7 | M13: =COUNT(orders[[#This Row],[count_id]]) -> 1 | Q13: =TEXT(orders[[#This Row],[Date]],"mmm") -> Feb | R13: 25461
... A1200: O002866 | B1200: 45848 | C1200: C0177 | D1200: P0799 | E1200: 6 | F1200: 43457 | G1200: 2787.58 | H1200: =(orders[[#This Row],[Profit]]/orders[[#This Row],[Sales]])*100 -> 6.4145707 | I1200: =orders[[#This Row],[Quantity]]*orders[[#This Row],[Cost Price]] -> 281472 | J1200: =TEXT(orders[[#This Row],[Date]],"mmm") -> Jul | K1200: 46912 | L1200: 9 | M1200: =COUNT(orders[[#This Row],[count_id]]) -> 1 | Q1200: =TEXT(orders[[#This Row],[Date]],"mmm") -> Jul | R1200: 43457
A1201: O004249 | B1201: 45890 | C1201: C0177 | D1201: P0138 | E1201: 3 | F1201: 32636 | G1201: 3485.77 | H1201: =(orders[[#This Row],[Profit]]/orders[[#This Row],[Sales]])*100 -> 10.680751 | I1201: =orders[[#This Row],[Quantity]]*orders[[#This Row],[Cost Price]] -> 123297 | J1201: =TEXT(orders[[#This Row],[Date]],"mmm") -> Aug | K1201: 41099 | L1201: 12 | M1201: =COUNT(orders[[#This Row],[count_id]]) -> 1 | R1201: 32636

Sheet products
A1: ProductID | B1: Product Name | C1: Category | D1: Cost Price
A2: P0001 | B2: Product_1 | C2: Stationery | D2: 31186
A3: P0002 | B3: Product_2 | C3: Stationery | D3: 19073
A4: P0003 | B4: Product_3 | C4: Accessories | D4: 13934
A5: P0004 | B5: Product_4 | C5: Accessories | D5: 21622 | H5: Row Labels | I5: Sum of Current Stock | K5: Row Labels | L5: Sum of Current Stock
A6: P0005 | B6: Product_5 | C6: Electronics | D6: 15661 | H6: P0006 | I6: 0 | K6: P0083 | L6: 992
A7: P0006 | B7: Product_6 | C7: Furniture | D7: 40770 | H7: P0084 | I7: 2 | K7: P0151 | L7: 991
A8: P0007 | B8: Product_7 | C8: Furniture | D8: 20642 | H8: P0106 | I8: 0 | K8: P0196 | L8: 997
A9: P0008 | B9: Product_8 | C9: Stationery | D9: 16109 | H9: P0167 | I9: 3 | K9: P0243 | L9: 998
A10: P0009 | B10: Product_9 | C10: Furniture | D10: 26854 | H10: P0305 | I10: 4 | K10: P0273 | L10: 992
A11: P0010 | B11: Product_10 | C11: Accessories | D11: 37926 | H11: P0312 | I11: 4 | K11: P0292 | L11: 997
A12: P0011 | B12: Product_11 | C12: Furniture | D12: 13755 | H12: P0463 | I12: 1 | K12: P0526 | L12: 992
A13: P0012 | B13: Product_12 | C13: Stationery | D13: 46983 | H13: P0854 | I13: 1 | K13: P0850 | L13: 999
A14: P0013 | B14: Product_13 | C14: Electronics | D14: 23230 | H14: Grand Total | I14: 15 | K14: P1080 | L14: 996
A15: P0014 | B15: Product_14 | C15: Accessories | D15: 33077 | K15: P1123 | L15: 995
A16: P0015 | B16: Product_15 | C16: Accessories | D16: 47866 | K16: Grand Total | L16: 9949
A17: P0016 | B17: Product_16 | C17: Accessories | D17: 21640
A18: P0017 | B18: Product_17 | C18: Furniture | D18: 10070
A19: P0018 | B19: Product_18 | C19: Electronics | D19: 37414
A20: P0019 | B20: Product_19 | C20: Stationery | D20: 430
A21: P0020 | B21: Product_20 | C21: Furniture | D21: 22949
A22: P0021 | B22: Product_21 | C22: Accessories | D22: 49001
A23: P0022 | B23: Product_22 | C23: Stationery | D23: 20779
A24: P0023 | B24: Product_23 | C24: Stationery | D24: 34236
A25: P0024 | B25: Product_24 | C25: Accessories | D25: 26311
A26: P0025 | B26: Product_25 | C26: Accessories | D26: 10812
A27: P0026 | B27: Product_26 | C27: Furniture | D27: 15954
A28: P0027 | B28: Product_27 | C28: Electronics | D28: 26224
... A1201: P1200 | B1201: Product_1200 | C1201: Furniture | D1201: 41099

Sheet sales_targets
A1: Date | B1: Target Sales | C1: month | D1: year
A2: 43831 | B2: 140369 | C2: =TEXT(sales_targets[[#This Row],[Date]],"MMM") -> Jan | D2: =YEAR(sales_targets[[#This Row],[Date]]) -> 2020
A3: 43862 | B3: 429986 | C3: =TEXT(sales_targets[[#This Row],[Date]],"MMM") -> Feb | D3: =YEAR(sales_targets[[#This Row],[Date]]) -> 2020
A4: 43891 | B4: 297706 | C4: =TEXT(sales_targets[[#This Row],[Date]],"MMM") -> Mar | D4: =YEAR(sales_targets[[#This Row],[Date]]) -> 2020
A5: 43922 | B5: 411190 | C5: =TEXT(sales_targets[[#This Row],[Date]],"MMM") -> Apr | D5: =YEAR(sales_targets[[#This Row],[Date]]) -> 2020
A6: 43952 | B6: 253508 | C6: =TEXT(sales_targets[[#This Row],[Date]],"MMM") -> May | D6: =YEAR(sales_targets[[#This Row],[Date]]) -> 2020
A7: 43983 | B7: 106808 | C7: =TEXT(sales_targets[[#This Row],[Date]],"MMM") -> Jun | D7: =YEAR(sales_targets[[#This Row],[Date]]) -> 2020 | G7: month | H7: sales | I7: mom growth%
A8: 44013 | B8: 356466 | C8: =TEXT(sales_targets[[#This Row],[Date]],"MMM") -> Jul | D8: =YEAR(sales_targets[[#This Row],[Date]]) -> 2020 | G8: Apr | H8: 2647992 | I8: =(Table6_1[[#This Row],[sales]]-H9)/Table6_1[[#This Row],[sales]] -> -0.040616815
A9: 44044 | B9: 106001 | C9: =TEXT(sales_targets[[#This Row],[Date]],"MMM") -> Aug | D9: =YEAR(sales_targets[[#This Row],[Date]]) -> 2020 | G9: Aug | H9: 2755545 | I9: =(Table6_1[[#This Row],[sales]]-H10)/Table6_1[[#This Row],[sales]] -> 0.00082379348
A10: 44075 | B10: 348480 | C10: =TEXT(sales_targets[[#This Row],[Date]],"MMM") -> Sep | D10: =YEAR(sales_targets[[#This Row],[Date]]) -> 2020 | G10: Dec | H10: 2753275 | I10: =(Table6_1[[#This Row],[sales]]-H11)/Table6_1[[#This Row],[sales]] -> -0.021737385
A11: 44105 | B11: 237529 | C11: =TEXT(sales_targets[[#This Row],[Date]],"MMM") -> Oct | D11: =YEAR(sales_targets[[#This Row],[Date]]) -> 2020 | G11: Feb | H11: 2813124 | I11: =(Table6_1[[#This Row],[sales]]-H12)/Table6_1[[#This Row],[sales]] -> 0.11115827
A12: 44136 | B12: 406188 | C12: =TEXT(sales_targets[[#This Row],[Date]],"MMM") -> Nov | D12: =YEAR(sales_targets[[#This Row],[Date]]) -> 2020 | G12: Jan | H12: 2500422 | I12: =(Table6_1[[#This Row],[sales]]-H13)/Table6_1[[#This Row],[sales]] -> 0.18048033
A13: 44166 | B13: 441542 | C13: =TEXT(sales_targets[[#This Row],[Date]],"MMM") -> Dec | D13: =YEAR(sales_targets[[#This Row],[Date]]) -> 2020 | G13: Jul | H13: 2049145 | I13: =(Table6_1[[#This Row],[sales]]-H14)/Table6_1[[#This Row],[sales]] -> -0.32368085
A14: 44197 | B14: 233317 | C14: =TEXT(sales_targets[[#This Row],[Date]],"MMM") -> Jan | D14: =YEAR(sales_targets[[#This Row],[Date]]) -> 2021 | G14: Jun | H14: 2712414 | I14: =(Table6_1[[#This Row],[sales]]-H15)/Table6_1[[#This Row],[sales]] -> 0.11339088
A15: 44228 | B15: 446938 | C15: =TEXT(sales_targets[[#This Row],[Date]],"MMM") -> Feb | D15: =YEAR(sales_targets[[#This Row],[Date]]) -> 2021 | G15: Mar | H15: 2404851 | I15: =(Table6_1[[#This Row],[sales]]-H16)/Table6_1[[#This Row],[sales]] -> -0.12838758
A16: 44256 | B16: 99904 | C16: =TEXT(sales_targets[[#This Row],[Date]],"MMM") -> Mar | D16: =YEAR(sales_targets[[#This Row],[Date]]) -> 2021 | G16: May | H16: 2713604 | I16: =(Table6_1[[#This Row],[sales]]-H17)/Table6_1[[#This Row],[sales]] -> 0.057917073
A17: 44287 | B17: 98314 | C17: =TEXT(sales_targets[[#This Row],[Date]],"MMM") -> Apr | D17: =YEAR(sales_targets[[#This Row],[Date]]) -> 2021 | G17: Nov | H17: 2556440 | I17: =(Table6_1[[#This Row],[sales]]-H18)/Table6_1[[#This Row],[sales]] -> -0.098165418
A18: 44317 | B18: 497092 | C18: =TEXT(sales_targets[[#This Row],[Date]],"MMM") -> May | D18: =YEAR(sales_targets[[#This Row],[Date]]) -> 2021 | G18: Oct | H18: 2807394 | I18: =(Table6_1[[#This Row],[sales]]-H19)/Table6_1[[#This Row],[sales]] -> 0.18201257
A19: 44348 | B19: 308433 | C19: =TEXT(sales_targets[[#This Row],[Date]],"MMM") -> Jun | D19: =YEAR(sales_targets[[#This Row],[Date]]) -> 2021 | G19: Sep | H19: 2296413 | I19: =(Table6_1[[#This Row],[sales]]-H8)/Table6_1[[#This Row],[sales]] -> -0.1530992
A20: 44378 | B20: 252820 | C20: =TEXT(sales_targets[[#This Row],[Date]],"MMM") -> Jul | D20: =YEAR(sales_targets[[#This Row],[Date]]) -> 2021
A21: 44409 | B21: 120053 | C21: =TEXT(sales_targets[[#This Row],[Date]],"MMM") -> Aug | D21: =YEAR(sales_targets[[#This Row],[Date]]) -> 2021 | I21: total_growth%
A22: 44440 | B22: 180048 | C22: =TEXT(sales_targets[[#This Row],[Date]],"MMM") -> Sep | D22: =YEAR(sales_targets[[#This Row],[Date]]) -> 2021 | I22: =SUM(Table6_1[mom growth%]) -> -0.11990433
A23: 44470 | B23: 358758 | C23: =TEXT(sales_targets[[#This Row],[Date]],"MMM") -> Oct | D23: =YEAR(sales_targets[[#This Row],[Date]]) -> 2021
A24: 44501 | B24: 419770 | C24: =TEXT(sales_targets[[#This Row],[Date]],"MMM") -> Nov | D24: =YEAR(sales_targets[[#This Row],[Date]]) -> 2021
A25: 44531 | B25: 462394 | C25: =TEXT(sales_targets[[#This Row],[Date]],"MMM") -> Dec | D25: =YEAR(sales_targets[[#This Row],[Date]]) -> 2021
A26: 44562 | B26: 233480 | C26: =TEXT(sales_targets[[#This Row],[Date]],"MMM") -> Jan | D26: =YEAR(sales_targets[[#This Row],[Date]]) -> 2022
A27: 44593 | B27: 254646 | C27: =TEXT(sales_targets[[#This Row],[Date]],"MMM") -> Feb | D27: =YEAR(sales_targets[[#This Row],[Date]]) -> 2022
A28: 44621 | B28: 123484 | C28: =TEXT(sales_targets[[#This Row],[Date]],"MMM") -> Mar | D28: =YEAR(sales_targets[[#This Row],[Date]]) -> 2022
A29: 44652 | B29: 87387 | C29: =TEXT(sales_targets[[#This Row],[Date]],"MMM") -> Apr | D29: =YEAR(sales_targets[[#This Row],[Date]]) -> 2022
A30: 44682 | B30: 247032 | C30: =TEXT(sales_targets[[#This Row],[Date]],"MMM") -> May | D30: =YEAR(sales_targets[[#This Row],[Date]]) -> 2022
A31: 44713 | B31: 310664 | C31: =TEXT(sales_targets[[#This Row],[Date]],"MMM") -> Jun | D31: =YEAR(sales_targets[[#This Row],[Date]]) -> 2022
A32: 44743 | B32: 96942 | C32: =TEXT(sales_targets[[#This Row],[Date]],"MMM") -> Jul | D32: =YEAR(sales_targets[[#This Row],[Date]]) -> 2022
A33: 44774 | B33: 233832 | C33: =TEXT(sales_targets[[#This Row],[Date]],"MMM") -> Aug | D33: =YEAR(sales_targets[[#This Row],[Date]]) -> 2022
A34: 44805 | B34: 338703 | C34: =TEXT(sales_targets[[#This Row],[Date]],"MMM") -> Sep | D34: =YEAR(sales_targets[[#This Row],[Date]]) -> 2022
... A1201: 80324 | B1201: 419841 | C1201: =TEXT(sales_targets[[#This Row],[Date]],"MMM") -> Dec | D1201: =YEAR(sales_targets[[#This Row],[Date]]) -> 2119
